Workbook

Sheet PIB trimestral
A1: Producto Interno Bruto trimestral a precios de mercado — variaciones
A2: Fuente: serie proporcionada por el usuario (INE). Celdas en azul = dato de entrada.
A4: Acumuladas 2026 proporcionadas (entrada)
A5: 2026 I | B5: 0.0006
A6: 2026 II | B6: -0.0334
A8: Año | B8: Trimestre | C8: Periodo | D8: PIB (nivel) | E8: Var. interanual | F8: Var. acumulada | G8: Var. 12 meses
A9: 2017 | B9: I | C9: 2017 I | D9: 75234
A10: 2017 | B10: II | C10: 2017 II | D10: 80177
A11: 2017 | B11: III | C11: 2017 III | D11: 82561
A12: 2017 | B12: IV | C12: 2017 IV | D12: 79387
A13: 2018 | B13: I | C13: 2018 I | D13: 77481 | E13: =D13/D9-1 -> 0.029866816 | F13: =SUM(D13:D13)/SUM(D9:D9)-1 -> 0.029866816
A14: 2018 | B14: II | C14: 2018 II | D14: 85436 | E14: =D14/D10-1 -> 0.065592377 | F14: =SUM(D13:D14)/SUM(D9:D10)-1 -> 0.04829774
A15: 2018 | B15: III | C15: 2018 III | D15: 82899 | E15: =D15/D11-1 -> 0.0040939427 | F15: =SUM(D13:D15)/SUM(D9:D11)-1 -> 0.032961861
A16: 2018 | B16: IV | C16: 2018 IV | D16: 80644 | E16: =D16/D12-1 -> 0.015833827 | F16: =SUM(D13:D16)/SUM(D9:D12)-1 -> 0.028677302 | G16: =SUM(D13:D16)/SUM(D9:D12)-1 -> 0.028677302
A17: 2019 | B17: I | C17: 2019 I | D17: 80210 | E17: =D17/D13-1 -> 0.035221538 | F17: =SUM(D17:D17)/SUM(D13:D13)-1 -> 0.035221538 | G17: =SUM(D14:D17)/SUM(D10:D13)-1 -> 0.029983793
A18: 2019 | B18: II | C18: 2019 II | D18: 86412 | E18: =D18/D14-1 -> 0.011423756 | F18: =SUM(D17:D18)/SUM(D13:D14)-1 -> 0.022741641 | G18: =SUM(D15:D18)/SUM(D11:D14)-1 -> 0.016314469
A19: 2019 | B19: III | C19: 2019 III | D19: 85874 | E19: =D19/D15-1 -> 0.035887043 | F19: =SUM(D17:D19)/SUM(D13:D15)-1 -> 0.027174797 | G19: =SUM(D16:D19)/SUM(D12:D15)-1 -> 0.024406294
A20: 2019 | B20: IV | C20: 2019 IV | D20: 78883 | E20: =D20/D16-1 -> -0.021836714 | F20: =SUM(D17:D20)/SUM(D13:D16)-1 -> 0.015067696 | G20: =SUM(D17:D20)/SUM(D13:D16)-1 -> 0.015067696
A21: 2020 | B21: I | C21: 2020 I | D21: 76532 | E21: =D21/D17-1 -> -0.045854632 | F21: =SUM(D21:D21)/SUM(D17:D17)-1 -> -0.045854632 | G21: =SUM(D18:D21)/SUM(D14:D17)-1 -> -0.0045201996
A22: 2020 | B22: II | C22: 2020 II | D22: 64029 | E22: =D22/D18-1 -> -0.25902652 | F22: =SUM(D21:D22)/SUM(D17:D18)-1 -> -0.15640792 | G22: =SUM(D19:D22)/SUM(D15:D18)-1 -> -0.075256311
A23: 2020 | B23: III | C23: 2020 III | D23: 71920 | E23: =D23/D19-1 -> -0.16249389 | F23: =SUM(D21:D23)/SUM(D17:D19)-1 -> -0.15847776 | G23: =SUM(D20:D23)/SUM(D16:D19)-1 -> -0.12540073
A24: 2020 | B24: IV | C24: 2020 IV | D24: 76750 | E24: =D24/D20-1 -> -0.027040047 | F24: =SUM(D21:D24)/SUM(D17:D20)-1 -> -0.12718971 | G24: =SUM(D21:D24)/SUM(D17:D20)-1 -> -0.12718971
A25: 2021 | B25: I | C25: 2021 I | D25: 75109 | E25: =D25/D21-1 -> -0.01859353 | F25: =SUM(D25:D25)/SUM(D21:D21)-1 -> -0.01859353 | G25: =SUM(D22:D25)/SUM(D18:D21)-1 -> -0.12173597
A26: 2021 | B26: II | C26: 2021 II | D26: 81541 | E26: =D26/D22-1 -> 0.27350107 | F26: =SUM(D25:D26)/SUM(D21:D22)-1 -> 0.11446276 | G26: =SUM(D23:D26)/SUM(D19:D22)-1 -> 6.5505473e-06
A27: 2021 | B27: III | C27: 2021 III | D27: 81169 | E27: =D27/D23-1 -> 0.12860122 | F27: =SUM(D25:D27)/SUM(D21:D23)-1 -> 0.11924831 | G27: =SUM(D24:D27)/SUM(D20:D23)-1 -> 0.079642646
A28: 2021 | B28: IV | C28: 2021 IV | D28: 80419 | E28: =D28/D24-1 -> 0.04780456 | F28: =SUM(D25:D28)/SUM(D21:D24)-1 -> 0.10029008 | G28: =SUM(D25:D28)/SUM(D21:D24)-1 -> 0.10029008
A29: 2022 | B29: I | C29: 2022 I | D29: 81682 | E29: =D29/D25-1 -> 0.087512815 | F29: =SUM(D29:D29)/SUM(D25:D25)-1 -> 0.087512815 | G29: =SUM(D26:D29)/SUM(D22:D25)-1 -> 0.12856835
A30: 2022 | B30: II | C30: 2022 II | D30: 85248 | E30: =D30/D26-1 -> 0.045461792 | F30: =SUM(D29:D30)/SUM(D25:D26)-1 -> 0.065624003 | G30: =SUM(D27:D30)/SUM(D23:D26)-1 -> 0.0759793
A31: 2022 | B31: III | C31: 2022 III | D31: 84141 | E31: =D31/D27-1 -> 0.036614964 | F31: =SUM(D29:D31)/SUM(D25:D27)-1 -> 0.05572305 | G31: =SUM(D28:D31)/SUM(D24:D27)-1 -> 0.05379106
A32: 2022 | B32: IV | C32: 2022 IV | D32: 79091 | E32: =D32/D28-1 -> -0.01651351 | F32: =SUM(D29:D32)/SUM(D25:D28)-1 -> 0.037468813 | G32: =SUM(D29:D32)/SUM(D25:D28)-1 -> 0.037468813
A33: 2023 | B33: I | C33: 2023 I | D33: 81529 | E33: =D33/D29-1 -> -0.0018731177 | F33: =SUM(D33:D33)/SUM(D29:D29)-1 -> -0.0018731177 | G33: =SUM(D30:D33)/SUM(D26:D29)-1 -> 0.016003153
A34: 2023 | B34: II | C34: 2023 II | D34: 88308 | E34: =D34/D30-1 -> 0.03589527 | F34: =SUM(D33:D34)/SUM(D29:D30)-1 -> 0.017414485 | G34: =SUM(D31:D34)/SUM(D27:D30)-1 -> 0.013853122
A35: 2023 | B35: III | C35: 2023 III | D35: 86547 | E35: =D35/D31-1 -> 0.028594859 | F35: =SUM(D33:D35)/SUM(D29:D31)-1 -> 0.021161345 | G35: =SUM(D32:D35)/SUM(D28:D31)-1 -> 0.012021479
A36: 2023 | B36: IV | C36: 2023 IV | D36: 82086 | E36: =D36/D32-1 -> 0.037867773 | F36: =SUM(D33:D36)/SUM(D29:D32)-1 -> 0.025163405 | G36: =SUM(D33:D36)/SUM(D29:D32)-1 -> 0.025163405
A37: 2024 | B37: I | C37: 2024 I | D37: 79584 | E37: =D37/D33-1 -> -0.023856542 | F37: =SUM(D37:D37)/SUM(D33:D33)-1 -> -0.023856542 | G37: =SUM(D34:D37)/SUM(D30:D33)-1 -> 0.019744916
A38: 2024 | B38: II | C38: 2024 II | D38: 89058 | E38: =D38/D34-1 -> 0.0084930018 | F38: =SUM(D37:D38)/SUM(D33:D34)-1 -> -0.0070361582 | G38: =SUM(D35:D38)/SUM(D31:D34)-1 -> 0.012628014
A39: 2024 | B39: III | C39: 2024 III | D39: 85333 | E39: =D39/D35-1 -> -0.01402706 | F39: =SUM(D37:D39)/SUM(D33:D35)-1 -> -0.0093960622 | G39: =SUM(D36:D39)/SUM(D32:D35)-1 -> 0.001746777
A40: 2024 | B40: IV | C40: 2024 IV | D40: 80694 | E40: =D40/D36-1 -> -0.016957825 | F40: =SUM(D37:D40)/SUM(D33:D36)-1 -> -0.011229947 | G40: =SUM(D37:D40)/SUM(D33:D36)-1 -> -0.011229947
A41: 2025 | B41: I | C41: 2025 I | D41: 78258 | E41: =D41/D37-1 -> -0.016661641 | F41: =SUM(D41:D41)/SUM(D37:D37)-1 -> -0.016661641 | G41: =SUM(D38:D41)/SUM(D34:D37)-1 -> -0.0094554639
A42: 2025 | B42: II | C42: 2025 II | D42: 86588 | E42: =D42/D38-1 -> -0.027734735 | F42: =SUM(D41:D42)/SUM(D37:D38)-1 -> -0.022509221 | G42: =SUM(D39:D42)/SUM(D35:D38)-1 -> -0.018981543
...

Sheet IpAEC ene-jun 2026
A1: Indicador proxy de Actividad Económica (IpAEC) — variación acumulada enero–junio 2026
A2: Datos de variación: Gráfico 1.11 (imagen proporcionada). Ponderaciones: SUPUESTO propio, no oficial.
A4: Actividad económica | B4: Var. acumulada (%) | C4: Ponderación supuesta | D4: Contribución aprox. (pp)
A5: Actividad extractiva | B5: 9.9 | C5: 0.08 | D5: =B5*C5 -> 0.792
A6: Agricultura, ganadería, silvicultura y pesca | B6: 3.2 | C6: 0.13 | D6: =B6*C6 -> 0.416
A7: Suministro de electricidad, agua y recolección de desechos sólidos | B7: 2 | C7: 0.023 | D7: =B7*C7 -> 0.046
A8: Administración pública, salud y educación de no mercado | B8: 0.3 | C8: 0.15 | D8: =B8*C8 -> 0.045
A9: Actividades comunales sociales (**) | B9: -1.4 | C9: 0.04 | D9: =B9*C9 -> -0.056
A10: Actividades de alojamiento y servicio de comidas y bebidas | B10: -2.6 | C10: 0.032 | D10: =B10*C10 -> -0.0832
A11: Actividades financieras y de seguros, inmobiliarias (*) | B11: -4.3 | C11: 0.15 | D11: =B11*C11 -> -0.645
A12: Industrias manufactureras | B12: -7.7 | C12: 0.11 | D12: =B12*C12 -> -0.847
A13: Comercio | B13: -8.6 | C13: 0.09 | D13: =B13*C13 -> -0.774
A14: Transporte y comunicaciones | B14: -9.5 | C14: 0.11 | D14: =B14*C14 -> -1.045
A15: Construcción | B15: -27.3 | C15: 0.035 | D15: =B15*C15 -> -0.9555
A16: Suma de contribuciones estimadas | C16: =SUM(C5:C15) -> 0.95 | D16: =SUM(D5:D15) -> -3.1067
A17: Total IpAEC publicado (ene–jun 2026) | B17: -3.34
A18: Discrepancia (suma estimada - total publicado) | D18: =D16-B17 -> 0.2333
A20: (*) y (**): la fuente reagrupa actividades respecto de la clasificación estándar del INE; revisar la nota al pie del documento original antes de comparar con series históricas.
A21: Las ponderaciones de la columna C son supuestos aproximados de la estructura del PIB boliviano, editables. Reemplazar por las ponderaciones oficiales del INE recalcula las contribuciones.

Sheet PIB primer semestre
A1: PIB acumulado del primer semestre (I + II trimestre) — índice 2017 = 100
A2: Calculado por fórmula desde la hoja 'PIB trimestral'. No editar las columnas B a D.
A4: Año | B4: PIB I+II trimestre | C4: Índice 2017 = 100 | D4: Var. interanual del semestre
A5: 2017 | B5: =SUM('PIB trimestral'!D9:D10) -> 155411 | C5: =B5/$B$5*100 -> 100
A6: 2018 | B6: =SUM('PIB trimestral'!D13:D14) -> 162917 | C6: =B6/$B$5*100 -> 104.82977 | D6: =B6/B5-1 -> 0.04829774
A7: 2019 | B7: =SUM('PIB trimestral'!D17:D18) -> 166622 | C7: =B7/$B$5*100 -> 107.21378 | D7: =B7/B6-1 -> 0.022741641
A8: 2020 | B8: =SUM('PIB trimestral'!D21:D22) -> 140561 | C8: =B8/$B$5*100 -> 90.444692 | D8: =B8/B7-1 -> -0.15640792
A9: 2021 | B9: =SUM('PIB trimestral'!D25:D26) -> 156650 | C9: =B9/$B$5*100 -> 100.79724 | D9: =B9/B8-1 -> 0.11446276
A10: 2022 | B10: =SUM('PIB trimestral'!D29:D30) -> 166930 | C10: =B10/$B$5*100 -> 107.41196 | D10: =B10/B9-1 -> 0.065624003
A11: 2023 | B11: =SUM('PIB trimestral'!D33:D34) -> 169837 | C11: =B11/$B$5*100 -> 109.28248 | D11: =B11/B10-1 -> 0.017414485
A12: 2024 | B12: =SUM('PIB trimestral'!D37:D38) -> 168642 | C12: =B12/$B$5*100 -> 108.51355 | D12: =B12/B11-1 -> -0.0070361582
A13: 2025 | B13: =SUM('PIB trimestral'!D41:D42) -> 164846 | C13: =B13/$B$5*100 -> 106.071 | D13: =B13/B12-1 -> -0.022509221
A14: 2026 | B14: =SUM('PIB trimestral'!D45:D46) -> 159340.14 | C14: =B14/$B$5*100 -> 102.52823 | D14: =B14/B13-1 -> -0.0334
A16: Nota: el semestre de 2026 incorpora los niveles derivados de las variaciones acumuladas publicadas; su nivel es estimado, no dato oficial del INE.
A17: El índice permite comparar el tamaño de la economía en la primera mitad de cada año, aislando el efecto estacional al comparar siempre los mismos dos trimestres.

Sheet INE trimestral sectorial
A1: Bolivia: medidas de volumen encadenadas del PIB por grupo de actividad, trimestral 2017–2025
A2: Millones de bolivianos encadenados. Copia literal de INE, Cuadro 02.01. No modificar.
A4: Actividad económica | B4: 2017 I | C4: 2017 II | D4: 2017 III | E4: 2017 IV | F4: 2018 I | G4: 2018 II | H4: 2018 III | I4: 2018 IV | J4: 2019 I | K4: 2019 II | L4: 2019 III | M4: 2019 IV | N4: 2020 I | O4: 2020 II | P4: 2020 III | Q4: 2020 IV | R4: 2021 I | S4: 2021 II | T4: 2021 III | U4: 2021 IV | V4: 2022 I | W4: 2022 II | X4: 2022 III | Y4: 2022 IV | Z4: 2023 I | AA4: 2023 II | AB4: 2023 III | AC4: 2023 IV | AD4: 2024 I | AE4: 2024 II | AF4: 2024 III | AG4: 2024 IV | AH4: 2025 I | AI4: 2025 II | AJ4: 2025 III | AK4: 2025 IV
A5: Actividad extractiva | B5: 6991.6739 | C5: 7680.1984 | D5: 8480.1742 | E5: 8315.1953 | F5: 7577.3823 | G5: 7889.4002 | H5: 8166.7352 | I5: 7631.6956 | J5: 7179.2624 | K5: 7314.4195 | L5: 8189.9709 | M5: 8038.6798 | N5: 7091.5449 | O5: 4281.0627 | P5: 6266.0529 | Q5: 7676.2718 | R5: 7204.8053 | S5: 7670.3914 | T5: 8234.8656 | U5: 8587.7641 | V5: 8061.0554 | W5: 7824.3626 | X5: 7725.119 | Y5: 7837.2874 | Z5: 7797.4918 | AA5: 7602.829 | AB5: 7431.3662 | AC5: 7080.5994 | AD5: 6829.142 | AE5: 6949.834 | AF5: 6766.3273 | AG5: 6603.397 | AH5: 6218.6883 | AI5: 6154.2482 | AJ5: 6687.9442 | AK5: 6914.2398
A6: Agricultura, ganadería, silvicultura y pesca | B6: 4891.8915 | C6: 8506.698 | D6: 6706.3933 | E6: 4259.0729 | F6: 5063.969 | G6: 9000.0371 | H6: 6570.1357 | I6: 4445.8861 | J6: 5341.67 | K6: 8907.7557 | L6: 7245.0528 | M6: 4380.4065 | N6: 5603.7298 | O6: 8866.819 | P6: 7589.464 | Q6: 5030.7803 | R6: 5777.6968 | S6: 9801.7685 | T6: 7506.28 | U6: 4908.8137 | V6: 5995.0888 | W6: 9981.8126 | X6: 7754.488 | Y6: 4744.1043 | Z6: 5896.4961 | AA6: 10363.029 | AB6: 8624.8935 | AC6: 5509.762 | AD6: 5557.8738 | AE6: 10895.806 | AF6: 7826.2043 | AG6: 4930.8669 | AH6: 5976.4271 | AI6: 10942.538 | AJ6: 8704.3655 | AK6: 5531.752
A7: Electricidad, agua y recolección de desechos | B7: 1258.1606 | C7: 1241.3057 | D7: 1284.977 | E7: 1341.3255 | F7: 1288.8561 | G7: 1319.2715 | H7: 1357.2592 | I7: 1433.0084 | J7: 1418.4064 | K7: 1444.9622 | L7: 1461.9245 | M7: 1477.8685 | N7: 1457.266 | O7: 1206.163 | P7: 1332.7094 | Q7: 1513.4573 | R7: 1446.8437 | S7: 1462.2001 | T7: 1517.4733 | U7: 1608.1214 | V7: 1569.4589 | W7: 1535.3942 | X7: 1574.0412 | Y7: 1653.5795 | Z7: 1606.5324 | AA7: 1588.0376 | AB7: 1647.1174 | AC7: 1761.8514 | AD7: 1706.9506 | AE7: 1645.9068 | AF7: 1649.9172 | AG7: 1743.828 | AH7: 1682.9024 | AI7: 1631.6034 | AJ7: 1685.4952 | AK7: 1730.8142
A8: Administración pública, salud y educación | B8: 11195.461 | C8: 9329.9288 | D8: 10345.375 | E8: 9600.4383 | F8: 10189.831 | G8: 10836.344 | H8: 10532.402 | I8: 9830.4641 | J8: 10199.613 | K8: 10756.894 | L8: 10650.678 | M8: 10192.558 | N8: 10208.8 | O8: 10472.263 | P8: 10591.394 | Q8: 10132.259 | R8: 10654.962 | S8: 10652.473 | T8: 10527.323 | U8: 10688.46 | V8: 11656.074 | W8: 9749.7809 | X8: 11310.08 | Y8: 10939.225 | Z8: 11038.073 | AA8: 11624.143 | AB8: 11588.995 | AC8: 11005.444 | AD8: 11454.36 | AE8: 11926.639 | AF8: 11687.886 | AG8: 11380.475 | AH8: 11565.035 | AI8: 12243.875 | AJ8: 12337.498 | AK8: 11212.95
A9: Actividades comunales, sociales y personales | B9: 3376.2931 | C9: 3317.9236 | D9: 3695.06 | E9: 3852.6116 | F9: 3636.5939 | G9: 3576.2038 | H9: 3212.1509 | I9: 4133.9265 | J9: 3608.142 | K9: 3349.5105 | L9: 3803.7953 | M9: 3951.1085 | N9: 4154.0968 | O9: 2034.9187 | P9: 3069.4897 | Q9: 4347.414 | R9: 3623.5903 | S9: 3257.5826 | T9: 3181.7965 | U9: 3511.5672 | V9: 3290.1746 | W9: 3416.7398 | X9: 3711.2114 | Y9: 3806.6006 | Z9: 3691.225 | AA9: 3561.3035 | AB9: 3768.7346 | AC9: 3860.3796 | AD9: 3613.2973 | AE9: 3584.7601 | AF9: 3835.1945 | AG9: 4101.6884 | AH9: 3875.7057 | AI9: 3602.9133 | AJ9: 3787.5269 | AK9: 3949.4098
A10: Alojamiento y servicio de comidas y bebidas | B10: 3251.5604 | C10: 3302.5314 | D10: 3520.2314 | E10: 3698.7054 | F10: 3417.8004 | G10: 3550.1067 | H10: 3739.4301 | I10: 3602.7234 | J10: 3689.9771 | K10: 3696.439 | L10: 3699.9575 | M10: 3387.6218 | N10: 3283.4918 | O10: 2380.9601 | P10: 2291.7758 | Q10: 2658.2098 | R10: 2905.7943 | S10: 3094.2116 | T10: 3255.6672 | U10: 3491.9741 | V10: 3515.7195 | W10: 3710.8358 | X10: 3901.4076 | Y10: 3723.0846 | Z10: 3640.5727 | AA10: 3882.884 | AB10: 4102.5736 | AC10: 3865.7343 | AD10: 3704.4577 | AE10: 3915.8095 | AF10: 4123.9296 | AG10: 4105.163 | AH10: 3947.6986 | AI10: 4161.1702 | AJ10: 4101.3508 | AK10: 4205.8807
A11: Financieras, seguros, inmobiliarias y prof. | B11: 11180.41 | C11: 11620.692 | D11: 11879.048 | E11: 12096.418 | F11: 12193.801 | G11: 12246.282 | H11: 11981.809 | I11: 11727.752 | J11: 12281.417 | K11: 12771.642 | L11: 12402.983 | M11: 12750.071 | N11: 12529.276 | O11: 11412.257 | P11: 11654.87 | Q11: 11756.387 | R11: 11852.388 | S11: 11592.587 | T11: 12598.625 | U11: 12860.949 | V11: 13143.116 | W11: 12666.76 | X11: 12954.85 | Y11: 12277.869 | Z11: 12721.805 | AA11: 12786.363 | AB11: 13161.022 | AC11: 14093.43 | AD11: 13403.378 | AE11: 13290.439 | AF11: 13375.098 | AG11: 12952.116 | AH11: 12502.453 | AI11: 12674.851 | AJ11: 13033.755 | AK11: 12979.176
A12: Industrias manufactureras | B12: 8490.6526 | C12: 9233.3166 | D12: 9627.6519 | E12: 9361.9743 | F12: 9035.41 | G12: 9530.9434 | H12: 9564.8975 | I12: 9693.2419 | J12: 9535.2519 | K12: 9811.0651 | L12: 10262.708 | M12: 9160.0268 | N12: 9147.8825 | O12: 6459.8522 | P12: 8157.9856 | Q12: 9439.4475 | R12: 9101.046 | S12: 9330.866 | T12: 9384.6069 | U12: 9362.9527 | V12: 9697.1846 | W12: 10166.256 | X12: 9860.2739 | Y12: 9327.7228 | Z12: 9802.6624 | AA12: 10479.31 | AB12: 10479.041 | AC12: 9879.3537 | AD12: 9393.5259 | AE12: 10697.823 | AF12: 10946.274 | AG12: 10059.525 | AH12: 9606.5712 | AI12: 10769.901 | AJ12: 10915.478 | AK12: 10109.678
A13: Comercio | B13: 6256.1454 | C13: 7275.704 | D13: 6640.926 | E13: 6054.024 | F13: 6340.562 | G13: 7677.6848 | H13: 6585.5091 | I13: 6473.2392 | J13: 6859.6142 | K13: 7795.0445 | L13: 6755.8366 | M13: 5966.587 | N13: 6035.4883 | O13: 5199.9682 | P13: 5337.7285 | Q13: 5875.5533 | R13: 6313.86 | S13: 7249.2061 | T13: 6234.8559 | U13: 6137.9298 | V13: 6769.5259 | W13: 7789.3546 | X13: 6735.9368 | Y13: 6293.4468 | Z13: 7002.8191 | AA13: 8062.6591 | AB13: 6710.7605 | AC13: 6114.1346 | AD13: 6290.5098 | AE13: 7795.1055 | AF13: 6696.829 | AG13: 6570.5688 | AH13: 6638.8762 | AI13: 7824.324 | AJ13: 6477.5718 | AK13: 6172.9383
A14: Transporte y comunicaciones | B14: 5270.9545 | C14: 5404.2723 | D14: 5630.2632 | E14: 5678.4557 | F14: 5442.6875 | G14: 5592.0086 | H14: 5774.025 | I14: 5866.4153 | J14: 5574.5113 | K14: 5746.232 | L14: 5916.1126 | M14: 5434.7911 | N14: 5099.8028 | O14: 3406.0016 | P14: 4371.931 | Q14: 5245.9869 | R14: 4872.5071 | S14: 5089.0708 | T14: 5370.4332 | U14: 5485.7868 | V14: 5194.0199 | W14: 5520.7437 | X14: 5683.6343 | Y14: 5476.6498 | Z14: 5290.8793 | AA14: 5523.1702 | AB14: 5713.223 | AC14: 5853.2396 | AD14: 5377.3148 | AE14: 5671.6734 | AF14: 5699.9551 | AG14: 5635.588 | AH14: 5363.2446 | AI14: 5485.4602 | AJ14: 5775.9308 | AK14: 5558.5502
A15: Construcción | B15: 5143.1445 | C15: 5136.2316 | D15: 5956.4448 | E15: 6251.0717 | F15: 4949.6976 | G15: 5689.0474 | H15: 6435.6125 | I15: 6640.0099 | J15: 5736.429 | K15: 6241.4123 | L15: 6607.6649 | M15: 5690.3891 | N15: 4032.2927 | O15: 2293.3379 | P15: 3984.5148 | Q15: 5126.7752 | R15: 3925.6478 | S15: 4554.6263 | T15: 5207.3298 | U15: 5335.3672 | V15: 4387.2819 | W15: 4558.8019 | X15: 4967.0521 | Y15: 5144.7627 | Z15: 4396.2159 | AA15: 4744.7548 | AB15: 5189.6053 | AC15: 5477.917 | AD15: 4732.1475 | AE15: 4729.8887 | AF15: 4975.3142 | AG15: 5274.0543 | AH15: 3983.5332 | AI15: 4336.7508 | AJ15: 4372.8292 | AK15: 4342.6769
A16: Derechos s/importaciones, IVAnd, IT y otros imp. indirectos | B16: 7927.8613 | C16: 8127.7194 | D16: 8794.0922 | E16: 8877.9469 | F16: 8344.7302 | G16: 8529.1386 | H16: 8978.7947 | I16: 9165.8082 | J16: 8823.9989 | K16: 8699.8114 | L16: 8912.1029 | M16: 8337.7664 | N16: 7719.6048 | O16: 5872.7335 | P16: 7234.8813 | Q16: 7857.2933 | R16: 7197.1733 | S16: 7777.6417 | T16: 8202.8171 | U16: 8373.8825 | V16: 8259.9245 | W16: 8333.226 | X16: 7790.3586 | Y16: 7714.9625 | Z16: 8731.0619 | AA16: 7944.8027 | AB16: 8176.812 | AC16: 7749.9817 | AD16: 7603.2023 | AE16: 7836.6222 | AF16: 7797.0761 | AG16: 7438.8252 | AH16: 6836.6447 | AI16: 6535.6541 | AJ16: 6501.7406 | AK16: 6758.4713
... A18: PRODUCTO INTERNO BRUTO (a precios de mercado) | B18: 75234.209 | C18: 80176.522 | D18: 82560.637 | E18: 79387.24 | F18: 77481.321 | G18: 85436.469 | H18: 82898.761 | I18: 80644.171 | J18: 80209.913 | K18: 86412.396 | L18: 85874.07 | M18: 78883.195 | N18: 76531.527 | O18: 64029.129 | P18: 71919.591 | Q18: 76749.604 | R18: 75108.514 | S18: 81540.754 | T18: 81169.02 | U18: 80418.567 | V18: 81682.424 | W18: 85248.039 | X18: 84140.721 | Y18: 79091.334 | Z18: 81528.982 | AA18: 88308.194 | AB18: 86547.399 | AC18: 82086.04 | AD18: 79583.898 | AE18: 89057.558 | AF18: 85333.097 | AG18: 80693.839 | AH18: 78258.33 | AI18: 86588.462 | AJ18: 84754.453 | AK18: 79771.429
A20: Nota del INE: la suma del volumen encadenado por grupos de actividad no es igual al total, por el método de encadenamiento.

Sheet Sectorial semestre
A1: PIB sectorial acumulado del primer semestre (I + II) — índice 2017 = 100
A2: 2017–2025: INE. 2026: estimado aplicando al semestre de 2025 las tasas del IpAEC del BCB (columna B, editable en azul).
A4: 1 · Nivel semestral I+II, millones de Bs encadenados
A5: Actividad económica | B5: Tasa IpAEC 2026 | C5: 2017 | D5: 2018 | E5: 2019 | F5: 2020 | G5: 2021 | H5: 2022 | I5: 2023 | J5: 2024 | K5: 2025 | L5: 2026
A6: Actividad extractiva | B6: 0.099 | C6: =SUM('INE trimestral sectorial'!B5:C5) -> 14671.872 | D6: =SUM('INE trimestral sectorial'!F5:G5) -> 15466.782 | E6: =SUM('INE trimestral sectorial'!J5:K5) -> 14493.682 | F6: =SUM('INE trimestral sectorial'!N5:O5) -> 11372.608 | G6: =SUM('INE trimestral sectorial'!R5:S5) -> 14875.197 | H6: =SUM('INE trimestral sectorial'!V5:W5) -> 15885.418 | I6: =SUM('INE trimestral sectorial'!Z5:AA5) -> 15400.321 | J6: =SUM('INE trimestral sectorial'!AD5:AE5) -> 13778.976 | K6: =SUM('INE trimestral sectorial'!AH5:AI5) -> 12372.936 | L6: =K6*(1+B6) -> 13597.857
A7: Agricultura, ganadería, silvicultura y pesca | B7: 0.032 | C7: =SUM('INE trimestral sectorial'!B6:C6) -> 13398.59 | D7: =SUM('INE trimestral sectorial'!F6:G6) -> 14064.006 | E7: =SUM('INE trimestral sectorial'!J6:K6) -> 14249.426 | F7: =SUM('INE trimestral sectorial'!N6:O6) -> 14470.549 | G7: =SUM('INE trimestral sectorial'!R6:S6) -> 15579.465 | H7: =SUM('INE trimestral sectorial'!V6:W6) -> 15976.901 | I7: =SUM('INE trimestral sectorial'!Z6:AA6) -> 16259.525 | J7: =SUM('INE trimestral sectorial'!AD6:AE6) -> 16453.68 | K7: =SUM('INE trimestral sectorial'!AH6:AI6) -> 16918.965 | L7: =K7*(1+B7) -> 17460.372
A8: Electricidad, agua y recolección de desechos | B8: 0.02 | C8: =SUM('INE trimestral sectorial'!B7:C7) -> 2499.4663 | D8: =SUM('INE trimestral sectorial'!F7:G7) -> 2608.1276 | E8: =SUM('INE trimestral sectorial'!J7:K7) -> 2863.3686 | F8: =SUM('INE trimestral sectorial'!N7:O7) -> 2663.429 | G8: =SUM('INE trimestral sectorial'!R7:S7) -> 2909.0438 | H8: =SUM('INE trimestral sectorial'!V7:W7) -> 3104.8531 | I8: =SUM('INE trimestral sectorial'!Z7:AA7) -> 3194.57 | J8: =SUM('INE trimestral sectorial'!AD7:AE7) -> 3352.8573 | K8: =SUM('INE trimestral sectorial'!AH7:AI7) -> 3314.5058 | L8: =K8*(1+B8) -> 3380.7959
A9: Administración pública, salud y educación | B9: 0.003 | C9: =SUM('INE trimestral sectorial'!B8:C8) -> 20525.39 | D9: =SUM('INE trimestral sectorial'!F8:G8) -> 21026.175 | E9: =SUM('INE trimestral sectorial'!J8:K8) -> 20956.507 | F9: =SUM('INE trimestral sectorial'!N8:O8) -> 20681.063 | G9: =SUM('INE trimestral sectorial'!R8:S8) -> 21307.435 | H9: =SUM('INE trimestral sectorial'!V8:W8) -> 21405.855 | I9: =SUM('INE trimestral sectorial'!Z8:AA8) -> 22662.216 | J9: =SUM('INE trimestral sectorial'!AD8:AE8) -> 23380.999 | K9: =SUM('INE trimestral sectorial'!AH8:AI8) -> 23808.91 | L9: =K9*(1+B9) -> 23880.337
A10: Actividades comunales, sociales y personales | B10: -0.014 | C10: =SUM('INE trimestral sectorial'!B9:C9) -> 6694.2167 | D10: =SUM('INE trimestral sectorial'!F9:G9) -> 7212.7977 | E10: =SUM('INE trimestral sectorial'!J9:K9) -> 6957.6524 | F10: =SUM('INE trimestral sectorial'!N9:O9) -> 6189.0155 | G10: =SUM('INE trimestral sectorial'!R9:S9) -> 6881.1728 | H10: =SUM('INE trimestral sectorial'!V9:W9) -> 6706.9143 | I10: =SUM('INE trimestral sectorial'!Z9:AA9) -> 7252.5285 | J10: =SUM('INE trimestral sectorial'!AD9:AE9) -> 7198.0574 | K10: =SUM('INE trimestral sectorial'!AH9:AI9) -> 7478.619 | L10: =K10*(1+B10) -> 7373.9183
A11: Alojamiento y servicio de comidas y bebidas | B11: -0.026 | C11: =SUM('INE trimestral sectorial'!B10:C10) -> 6554.0919 | D11: =SUM('INE trimestral sectorial'!F10:G10) -> 6967.9071 | E11: =SUM('INE trimestral sectorial'!J10:K10) -> 7386.4161 | F11: =SUM('INE trimestral sectorial'!N10:O10) -> 5664.4519 | G11: =SUM('INE trimestral sectorial'!R10:S10) -> 6000.0059 | H11: =SUM('INE trimestral sectorial'!V10:W10) -> 7226.5552 | I11: =SUM('INE trimestral sectorial'!Z10:AA10) -> 7523.4567 | J11: =SUM('INE trimestral sectorial'!AD10:AE10) -> 7620.2672 | K11: =SUM('INE trimestral sectorial'!AH10:AI10) -> 8108.8687 | L11: =K11*(1+B11) -> 7898.0381
A12: Financieras, seguros, inmobiliarias y prof. | B12: -0.043 | C12: =SUM('INE trimestral sectorial'!B11:C11) -> 22801.102 | D12: =SUM('INE trimestral sectorial'!F11:G11) -> 24440.084 | E12: =SUM('INE trimestral sectorial'!J11:K11) -> 25053.059 | F12: =SUM('INE trimestral sectorial'!N11:O11) -> 23941.533 | G12: =SUM('INE trimestral sectorial'!R11:S11) -> 23444.975 | H12: =SUM('INE trimestral sectorial'!V11:W11) -> 25809.876 | I12: =SUM('INE trimestral sectorial'!Z11:AA11) -> 25508.168 | J12: =SUM('INE trimestral sectorial'!AD11:AE11) -> 26693.817 | K12: =SUM('INE trimestral sectorial'!AH11:AI11) -> 25177.304 | L12: =K12*(1+B12) -> 24094.68
A13: Industrias manufactureras | B13: -0.077 | C13: =SUM('INE trimestral sectorial'!B12:C12) -> 17723.969 | D13: =SUM('INE trimestral sectorial'!F12:G12) -> 18566.353 | E13: =SUM('INE trimestral sectorial'!J12:K12) -> 19346.317 | F13: =SUM('INE trimestral sectorial'!N12:O12) -> 15607.735 | G13: =SUM('INE trimestral sectorial'!R12:S12) -> 18431.912 | H13: =SUM('INE trimestral sectorial'!V12:W12) -> 19863.441 | I13: =SUM('INE trimestral sectorial'!Z12:AA12) -> 20281.973 | J13: =SUM('INE trimestral sectorial'!AD12:AE12) -> 20091.349 | K13: =SUM('INE trimestral sectorial'!AH12:AI12) -> 20376.472 | L13: =K13*(1+B13) -> 18807.484
A14: Comercio | B14: -0.086 | C14: =SUM('INE trimestral sectorial'!B13:C13) -> 13531.849 | D14: =SUM('INE trimestral sectorial'!F13:G13) -> 14018.247 | E14: =SUM('INE trimestral sectorial'!J13:K13) -> 14654.659 | F14: =SUM('INE trimestral sectorial'!N13:O13) -> 11235.457 | G14: =SUM('INE trimestral sectorial'!R13:S13) -> 13563.066 | H14: =SUM('INE trimestral sectorial'!V13:W13) -> 14558.881 | I14: =SUM('INE trimestral sectorial'!Z13:AA13) -> 15065.478 | J14: =SUM('INE trimestral sectorial'!AD13:AE13) -> 14085.615 | K14: =SUM('INE trimestral sectorial'!AH13:AI13) -> 14463.2 | L14: =K14*(1+B14) -> 13219.365
A15: Transporte y comunicaciones | B15: -0.095 | C15: =SUM('INE trimestral sectorial'!B14:C14) -> 10675.227 | D15: =SUM('INE trimestral sectorial'!F14:G14) -> 11034.696 | E15: =SUM('INE trimestral sectorial'!J14:K14) -> 11320.743 | F15: =SUM('INE trimestral sectorial'!N14:O14) -> 8505.8044 | G15: =SUM('INE trimestral sectorial'!R14:S14) -> 9961.578 | H15: =SUM('INE trimestral sectorial'!V14:W14) -> 10714.764 | I15: =SUM('INE trimestral sectorial'!Z14:AA14) -> 10814.049 | J15: =SUM('INE trimestral sectorial'!AD14:AE14) -> 11048.988 | K15: =SUM('INE trimestral sectorial'!AH14:AI14) -> 10848.705 | L15: =K15*(1+B15) -> 9818.0779
A16: Construcción | B16: -0.273 | C16: =SUM('INE trimestral sectorial'!B15:C15) -> 10279.376 | D16: =SUM('INE trimestral sectorial'!F15:G15) -> 10638.745 | E16: =SUM('INE trimestral sectorial'!J15:K15) -> 11977.841 | F16: =SUM('INE trimestral sectorial'!N15:O15) -> 6325.6306 | G16: =SUM('INE trimestral sectorial'!R15:S15) -> 8480.2742 | H16: =SUM('INE trimestral sectorial'!V15:W15) -> 8946.0838 | I16: =SUM('INE trimestral sectorial'!Z15:AA15) -> 9140.9707 | J16: =SUM('INE trimestral sectorial'!AD15:AE15) -> 9462.0363 | K16: =SUM('INE trimestral sectorial'!AH15:AI15) -> 8320.284 | L16: =K16*(1+B16) -> 6048.8465
A17: Suma de los once sectores | C17: =SUM(C6:C16) -> 139355.15 | D17: =SUM(D6:D16) -> 146043.92 | E17: =SUM(E6:E16) -> 149259.67 | F17: =SUM(F6:F16) -> 126657.28 | G17: =SUM(G6:G16) -> 141434.12 | H17: =SUM(H6:H16) -> 150199.54 | I17: =SUM(I6:I16) -> 153103.26 | J17: =SUM(J6:J16) -> 153166.64 | ... L17: =SUM(L6:L16) -> 145579.77
A18: Derechos s/import., IVAnd, IT y otros (2026: residuo) | C18: =SUM('INE trimestral sectorial'!B16:C16) -> 16055.581 | D18: =SUM('INE trimestral sectorial'!F16:G16) -> 16873.869 | E18: =SUM('INE trimestral sectorial'!J16:K16) -> 17523.81 | F18: =SUM('INE trimestral sectorial'!N16:O16) -> 13592.338 | G18: =SUM('INE trimestral sectorial'!R16:S16) -> 14974.815 | H18: =SUM('INE trimestral sectorial'!V16:W16) -> 16593.15 | I18: =SUM('INE trimestral sectorial'!Z16:AA16) -> 16675.865 | J18: =SUM('INE trimestral sectorial'!AD16:AE16) -> 15439.824 | K18: =SUM('INE trimestral sectorial'!AH16:AI16) -> 13372.299 | L18: =L20-L17 -> 13760.373
A19: Discrepancia de encadenamiento (VAB − suma sectores) | C19: =SUM('INE trimestral sectorial'!B17:C17)-C17 -> 0 | D19: =SUM('INE trimestral sectorial'!F17:G17)-D17 -> 0 | E19: =SUM('INE trimestral sectorial'!J17:K17)-E17 -> -193.44682 | F19: =SUM('INE trimestral sectorial'!N17:O17)-F17 -> 47.185552 | G19: =SUM('INE trimestral sectorial'!R17:S17)-G17 -> -104.73452 | H19: =SUM('INE trimestral sectorial'!V17:W17)-H17 -> -83.382299 | I19: =SUM('INE trimestral sectorial'!Z17:AA17)-I17 -> -194.52163 | J19: =SUM('INE trimestral sectorial'!AD17:AE17)-J17 -> -556.23259 | K19: =SUM('INE trimestral sectorial'!AH17:AI17)-K17 -> -822.22948
A20: PRODUCTO INTERNO BRUTO, semestre I+II | C20: ='PIB primer semestre'!B5 -> 155411 | D20: ='PIB primer semestre'!B6 -> 162917 | E20: ='PIB primer semestre'!B7 -> 166622 | F20: ='PIB primer semestre'!B8 -> 140561 | G20: ='PIB primer semestre'!B9 -> 156650 | H20: ='PIB primer semestre'!B10 -> 166930 | I20: ='PIB primer semestre'!B11 -> 169837 | J20: ='PIB primer semestre'!B12 -> 168642 | K20: ='PIB primer semestre'!B13 -> 164846 | L20: ='PIB primer semestre'!B14 -> 159340.14
A23: 2 · Índice del semestre I+II, 2017 = 100
A24: Actividad económica | B24: Tasa IpAEC 2026 | C24: 2017 | D24: 2018 | E24: 2019 | F24: 2020 | G24: 2021 | H24: 2022 | I24: 2023 | J24: 2024 | K24: 2025 | L24: 2026
A25: Actividad extractiva | C25: =C6/$C$6*100 -> 100 | D25: =D6/$C$6*100 -> 105.41792 | E25: =E6/$C$6*100 -> 98.785496 | F25: =F6/$C$6*100 -> 77.512994 | G25: =G6/$C$6*100 -> 101.38581 | H25: =H6/$C$6*100 -> 108.27124 | I25: =I6/$C$6*100 -> 104.96493 | J25: =J6/$C$6*100 -> 93.91423 | ... L25: =L6/$C$6*100 -> 92.679767
A26: Agricultura, ganadería, silvicultura y pesca | C26: =C7/$C$7*100 -> 100 | D26: =D7/$C$7*100 -> 104.96632 | E26: =E7/$C$7*100 -> 106.35019 | F26: =F7/$C$7*100 -> 108.00054 | G26: =G7/$C$7*100 -> 116.27691 | H26: =H7/$C$7*100 -> 119.24316 | I26: =I7/$C$7*100 -> 121.35251 | J26: =J7/$C$7*100 -> 122.80158 | ... L26: =L7/$C$7*100 -> 130.315
A27: Electricidad, agua y recolección de desechos | C27: =C8/$C$8*100 -> 100 | D27: =D8/$C$8*100 -> 104.34738 | E27: =E8/$C$8*100 -> 114.5592 | F27: =F8/$C$8*100 -> 106.55991 | G27: =G8/$C$8*100 -> 116.3866 | H27: =H8/$C$8*100 -> 124.22064 | I27: =I8/$C$8*100 -> 127.81008 | J27: =J8/$C$8*100 -> 134.14293 | ... L27: =L8/$C$8*100 -> 135.26071
A28: Administración pública, salud y educación | C28: =C9/$C$9*100 -> 100 | D28: =D9/$C$9*100 -> 102.43983 | E28: =E9/$C$9*100 -> 102.10041 | F28: =F9/$C$9*100 -> 100.75845 | G28: =G9/$C$9*100 -> 103.81014 | H28: =H9/$C$9*100 -> 104.28964 | I28: =I9/$C$9*100 -> 110.41065 | J28: =J9/$C$9*100 -> 113.91257 | ... L28: =L9/$C$9*100 -> 116.34535
A29: Actividades comunales, sociales y personales | C29: =C10/$C$10*100 -> 100 | D29: =D10/$C$10*100 -> 107.7467 | E29: =E10/$C$10*100 -> 103.93527 | F29: =F10/$C$10*100 -> 92.45317 | G29: =G10/$C$10*100 -> 102.7928 | H29: =H10/$C$10*100 -> 100.18968 | I29: =I10/$C$10*100 -> 108.34021 | J29: =J10/$C$10*100 -> 107.52651 | ... L29: =L10/$C$10*100 -> 110.15356
A30: Alojamiento y servicio de comidas y bebidas | C30: =C11/$C$11*100 -> 100 | D30: =D11/$C$11*100 -> 106.31385 | E30: =E11/$C$11*100 -> 112.69931 | F30: =F11/$C$11*100 -> 86.426191 | G30: =G11/$C$11*100 -> 91.545954 | H30: =H11/$C$11*100 -> 110.26021 | I30: =I11/$C$11*100 -> 114.79022 | J30: =J11/$C$11*100 -> 116.26732 | ... L30: =L11/$C$11*100 -> 120.50545
A31: Financieras, seguros, inmobiliarias y prof. | C31: =C12/$C$12*100 -> 100 | D31: =D12/$C$12*100 -> 107.18817 | E31: =E12/$C$12*100 -> 109.87653 | F31: =F12/$C$12*100 -> 105.00165 | G31: =G12/$C$12*100 -> 102.82387 | H31: =H12/$C$12*100 -> 113.19574 | I31: =I12/$C$12*100 -> 111.87252 | J31: =J12/$C$12*100 -> 117.07249 | ... L31: =L12/$C$12*100 -> 105.67331
A32: Industrias manufactureras | C32: =C13/$C$13*100 -> 100 | D32: =D13/$C$13*100 -> 104.7528 | E32: =E13/$C$13*100 -> 109.15341 | F32: =F13/$C$13*100 -> 88.060042 | G32: =G13/$C$13*100 -> 103.99427 | H32: =H13/$C$13*100 -> 112.07106 | I32: =I13/$C$13*100 -> 114.43245 | J32: =J13/$C$13*100 -> 113.35694 | ... L32: =L13/$C$13*100 -> 106.11327
A33: Comercio | C33: =C14/$C$14*100 -> 100 | D33: =D14/$C$14*100 -> 103.59446 | E33: =E14/$C$14*100 -> 108.29753 | F33: =F14/$C$14*100 -> 83.029719 | G33: =G14/$C$14*100 -> 100.23069 | H33: =H14/$C$14*100 -> 107.58973 | I33: =I14/$C$14*100 -> 111.33348 | J33: =J14/$C$14*100 -> 104.09232 | ... L33: =L14/$C$14*100 -> 97.690749
A34: Transporte y comunicaciones | C34: =C15/$C$15*100 -> 100 | D34: =D15/$C$15*100 -> 103.36732 | E34: =E15/$C$15*100 -> 106.04686 | F34: =F15/$C$15*100 -> 79.677974 | G34: =G15/$C$15*100 -> 93.314907 | H34: =H15/$C$15*100 -> 100.37036 | I34: =I15/$C$15*100 -> 101.30042 | J34: =J15/$C$15*100 -> 103.5012 | ... L34: =L15/$C$15*100 -> 91.970673
A35: Construcción | C35: =C16/$C$16*100 -> 100 | D35: =D16/$C$16*100 -> 103.49602 | E35: =E16/$C$16*100 -> 116.52304 | F35: =F16/$C$16*100 -> 61.537106 | G35: =G16/$C$16*100 -> 82.497947 | H35: =H16/$C$16*100 -> 87.029443 | I35: =I16/$C$16*100 -> 88.925346 | J35: =J16/$C$16*100 -> 92.048741 | ... L35: =L16/$C$16*100 -> 58.844491
A36: PRODUCTO INTERNO BRUTO | C36: =C20/$C$20*100 -> 100 | D36: =D20/$C$20*100 -> 104.82977 | E36: =E20/$C$20*100 -> 107.21378 | F36: =F20/$C$20*100 -> 90.444692 | G36: =G20/$C$20*100 -> 100.79724 | H36: =H20/$C$20*100 -> 107.41196 | I36: =I20/$C$20*100 -> 109.28248 | J36: =J20/$C$20*100 -> 108.51355 | ... L36: =L20/$C$20*100 -> 102.52823
A39: 3 · Contribución al crecimiento del semestre 2026 (puntos porcentuales)
A40: Actividad económica | B40: Δ nivel 2026 vs 2025 | C40: Peso en el PIB 2025 | D40: Contribución (pp)
A41: Actividad extractiva | B41: =L6-K6 -> 1224.9207 | C41: =K6/$K$20 -> 0.075057547 | D41: =B41/$K$20*100 -> 0.74306972
A42: Agricultura, ganadería, silvicultura y pesca | B42: =L7-K7 -> 541.40688 | C42: =K7/$K$20 -> 0.10263497 | D42: =B42/$K$20*100 -> 0.32843192
A43: Electricidad, agua y recolección de desechos | B43: =L8-K8 -> 66.290116 | C43: =K8/$K$20 -> 0.02010668 | D43: =B43/$K$20*100 -> 0.04021336
A44: Administración pública, salud y educación | B44: =L9-K9 -> 71.42673 | C44: =K9/$K$20 -> 0.14443123 | D44: =B44/$K$20*100 -> 0.043329368
A45: Actividades comunales, sociales y personales | B45: =L10-K10 -> -104.70067 | C45: =K10/$K$20 -> 0.045367306 | D45: =B45/$K$20*100 -> -0.063514229
...
